<?xml version="1.0"?>
<robot name="simple_arm">

  <link name="world"/>

  <link name="base_link">
    <visual>
      <geometry>
        <cylinder length="0.2" radius="0.1"/>
      </geometry>
      <origin rpy="0 0 0" xyz="0 0 0.1"/>
    </visual>
    <collision>
      <geometry>
        <cylinder length="0.2" radius="0.1"/>
      </geometry>
      <origin rpy="0 0 0" xyz="0 0 0.1"/>
    </collision>
    <inertial>
      <mass value="1.0"/>
      <origin xyz="0 0 0.1"/>
      <inertia ixx="0.01" ixy="0" ixz="0" iyy="0.01" iyz="0" izz="0.02"/>
    </inertial>
  </link>

  <joint name="world_to_base" type="fixed">
    <parent link="world"/>
    <child link="base_link"/>
    <origin xyz="0 0 0.5" rpy="0 0 0"/>
  </joint>

  <link name="link1">
    <visual>
      <geometry>
        <box size="0.5 0.1 0.1"/>
      </geometry>
      <origin rpy="0 0 0" xyz="0.25 0 0"/>
    </visual>
     <collision>
      <geometry>
        <box size="0.5 0.1 0.1"/>
      </geometry>
      <origin rpy="0 0 0" xyz="0.25 0 0"/>
    </collision>
    <inertial>
      <mass value="0.5"/>
      <origin xyz="0.25 0 0"/>
      <inertia ixx="0.001" ixy="0" ixz="0" iyy="0.002" iyz="0" izz="0.002"/>
    </inertial>
  </link>

  <joint name="joint1" type="revolute">
    <parent link="base_link"/>
    <child link="link1"/>
    <origin xyz="0 0 0.2" rpy="0 0 0"/>
    <axis xyz="0 0 1"/>
    <limit lower="-1.57" upper="1.57" effort="100" velocity="1.0"/>
    <dynamics damping="0.1" friction="0.05"/>
  </joint>

</robot>